Workbook
Name EVENTO_1: #REF!
Name EVENTO_1: #REF!
Name EVENTO_1: 'Configuracion INFIDELIDAD EMPLE'!$D$14:$E$14
Name EVENTO_2: #REF!
Name EVENTO_2: #REF!
Name EVENTO_2: 'Configuracion INFIDELIDAD EMPLE'!$D$15:$E$15
Name EVENTO_3: #REF!
Name EVENTO_3: #REF!
Name EVENTO_3: 'Configuracion INFIDELIDAD EMPLE'!$D$16:$E$16
Name EVENTO_4: #REF!
Name EVENTO_4: #REF!
Name EVENTO_4: 'Configuracion INFIDELIDAD EMPLE'!$D$17
Name Facturacion: #REF!
Name Facturacion: #REF!
Name Facturacion: #REF!
Name FCINCO: #REF!
Name FCINCO: #REF!
Name FCINCO: #REF!
Name FCUATRO: #REF!
Name FCUATRO: #REF!
Name FCUATRO: #REF!
Name FDOS: #REF!
Name FDOS: #REF!
Name FDOS: #REF!
Name FOS: #REF!
Name FSEIS: #REF!
Name FSIETE: #REF!
Name FTRES: #REF!
Name FUNO: #REF!
Name INGRESO1: 'LISTAd&o'!$B$24:$B$31
Name INGRESO2: 'LISTAd&o'!$C$24:$C$35
Name INGRESO3: 'LISTAd&o'!$D$24:$D$36
Name INGRESO4: 'LISTAd&o'!$E$24:$E$36
Name INGRESO5: 'LISTAd&o'!$F$24:$F$36
Name INGRESO6: 'LISTAd&o'!$G$24:$G$36
Name INGRESO7: 'LISTAd&o'!$H$24:$H$32
Name INGRESO8: 'LISTAd&o'!$I$24:$I$32
Name INGRESO9: 'LISTAd&o'!$J$24:$J$32
Name LIM_1: 'Configuracion CYBER'!$D$4:$E$4
Name LIM_1: #REF!
Name LIM_1: #REF!
Name LIM_1: 'Configuracion INFIDELIDAD EMPLE'!$D$6
Name LIM_2: 'Configuracion CYBER'!$D$5:$F$5
Name LIM_2: #REF!
Name LIM_2: #REF!
Name LIM_2: 'Configuracion INFIDELIDAD EMPLE'!$D$7:$E$7
Name LIM_3: 'Configuracion CYBER'!$D$6:$G$6
Name LIM_3: #REF!
Name LIM_3: #REF!
Name LIM_3: 'Configuracion INFIDELIDAD EMPLE'!$D$8:$F$8
Name LIM_4: 'Configuracion CYBER'!$D$7:$G$7
Name LIM_4: #REF!
Name LIM_4: #REF!
Name LIM_4: 'Configuracion INFIDELIDAD EMPLE'!$D$9:$F$9
Name LIM_5: 'Configuracion CYBER'!$D$8:$H$8
Name LIM_6: 'Configuracion CYBER'!$D$9:$H$9
Name LIM_7: 'Configuracion CYBER'!$D$10:$H$10
Name limite: PRIMAS!$B$20:$B$25
Name OPC1000000000: COP1.000.000.000[COP1.000.000.000]
Name OPC1500000000: COP1.500.000.000[COP1.500.000.000]

Sheet ENTRADAS
A1: ENTRADAS D&O
A2: NIT
A3: FACTURACIÓN ANUAL TOTAL | B3: Hasta COP 85.000.000.000
A4: ALTERNATIVA 1 LIMITE | B4: 1000000000
A5: ALTERNATIVA 2 LIMITE | B5: 1000000000
A6: ALTERNATIVA 3 LIMITE | B6: 1000000000
A8: ANEXO DE COBERTURA | B8: SI
A9: SECTOR | B9: Otros
A13: ENTRADAS INFIDELIDAD DE EMPLEADOS
A14: NIT
A15: FACTURACIÓN ANUAL TOTAL | B15: 45000000000
A16: ALTERNATIVA 1 LIMITE POR EVENTO | B16: COP1.000.000.000
A17: ALTERNATIVA 2 LIMITE POR EVENTO | B17: COP1.000.000.000
A18: ALTERNATIVA 3 LIMITE POR EVENTO | B18: COP1.000.000.000
A19: ALTERNATIVA 1 LIMITE POR AGREGADO | B19: COP2.000.000.000
A20: ALTERNATIVA 2 LIMITE POR AGREGADO | B20: COP2.000.000.000
A21: ALTERNITIVA 3 LIMITE POR AGREGADO | B21: COP2.000.000.000
A25: ENTRADAS CYBER
A26: NIT
A27: FACTURACIÓN ANUAL TOTAL | B27: 45000000000
A28: ALTERNATIVA 1 LIMITE POR EVENTO | B28: 1000000000
A29: ALTERNATIVA 2 LIMITE POR EVENTO | B29: 1000000000
A30: ALTERNATIVA 3 LIMITE POR EVENTO | B30: 1000000000
A33: PI
A34: NIT
A35: FACTURACIÓN | B35: Hasta COP 3.000.000.000
A36: Límite de responsabilidad 1 | B36: 500000000
A37: Límite de responsabilidad 2 | B37: 2000000000
A38: Límite de responsabilidad 3 | B38: 5000000000
A39: ACTIVIDAD | B39: CONTADORES
A40: DEDUCIBLE 1 | B40: 30000000
A41: DEDUCIBLE 2 | B41: 40000000
A42: DEDUCIBLE 3 | B42: 55000000

Sheet SALIDAS
A1: D&O
A2: PRIMA ANUAL COMERCIAL (BRUTA) ANTES DE IMPUESTOS
A3: ALTERNATIVA 1 | B3: ='CALCULOSD&O'!B2 -> 2650000
A4: ALTERNATIVA 2 | B4: ='CALCULOSD&O'!B3 -> 2650000
A5: ALTERNATIVA 3 | B5: ='CALCULOSD&O'!B4 -> 2650000
A7: NOTA DE COBERTURA | B7: LIMITE | C7: DEDUCIBLE
A8: 1 | B8: ='CALCULOSD&O'!D8 -> 200000000 | C8: ='CALCULOSD&O'!H8 -> 15000000
A9: 2 | B9: ='CALCULOSD&O'!D9 -> 200000000 | C9: ='CALCULOSD&O'!H9 -> 15000000
A10: 3 | B10: ='CALCULOSD&O'!D10 -> 200000000 | C10: ='CALCULOSD&O'!H10 -> 15000000
A13: INFIDELIDAD DE EMPLEADOS
A14: PRIMA ANUAL COMERCIAL (BRUTA) ANTES DE IMPUESTOS | B14: DEDUCIBLE | C14: PRIMA
A15: ALTERNATIVA 1 | B15: ='CALCULOS INFIDELIDAD DE EMPLEAD'!B5 -> COP50.000.000 | C15: ='CALCULOS INFIDELIDAD DE EMPLEAD'!B2 -> -
A16: ALTERNATIVA 2 | B16: ='CALCULOS INFIDELIDAD DE EMPLEAD'!B6 -> COP50.000.000 | C16: ='CALCULOS INFIDELIDAD DE EMPLEAD'!B3 -> -
A17: ALTERNATIVA 3 | B17: ='CALCULOS INFIDELIDAD DE EMPLEAD'!B7 -> COP50.000.000 | C17: ='CALCULOS INFIDELIDAD DE EMPLEAD'!B4 -> -
A21: CYBER
A22: PRIMA ANUAL COMERCIAL (BRUTA) ANTES DE IMPUESTOS | B22: DEDUCIBLE | C22: PRIMA
A23: ALTERNATIVA 1 | B23: ='CALCULOS CYBER'!B3 -> 50000000 | C23: ='CALCULOS CYBER'!C3 -> 8563362.5
A24: ALTERNATIVA 2 | B24: ='CALCULOS CYBER'!B4 -> 50000000 | C24: ='CALCULOS CYBER'!C4 -> 8563362.5
A25: ALTERNATIVA 3 | B25: ='CALCULOS CYBER'!B5 -> 50000000 | C25: ='CALCULOS CYBER'!C5 -> 8563362.5
A28: PI
A29: LIMITE | B29: DEDUCIBLE | C29: PRIMA ANUAL COMERCIAL (BRUTA) ANTES DE IMPUESTOS
A30: =ENTRADAS!B36 -> 500000000 | B30: =ENTRADAS!B40 -> 30000000 | C30: ='busqueda pi'!C13 -> 4800000
A31: =ENTRADAS!B37 -> 2000000000 | B31: =ENTRADAS!B41 -> 40000000 | C31: ='busqueda pi'!C14 -> 14900000
A32: =ENTRADAS!B38 -> 5000000000 | B32: =ENTRADAS!B42 -> 55000000 | C32: ='busqueda pi'!C15 -> 33700000

Sheet busqueda pi
A1: PI
A2: LIMITE | B2: DEDUCIBLE | C2: PRIMA ANUAL COMERCIAL (BRUTA) ANTES DE IMPUESTOS
A3: =ENTRADAS!B36 -> 500000000 | B3: =ENTRADAS!B40 -> 30000000 | C3: =IF(B13=B9,C9,IF(B13=B8,C8,C10)) -> 4800000
A4: =ENTRADAS!B37 -> 2000000000 | B4: =ENTRADAS!B41 -> 40000000 | C4: =IF(B13=F9,G9,IF(B13=F8,G8,G10)) -> 14900000
A5: =ENTRADAS!B38 -> 5000000000 | B5: =ENTRADAS!B42 -> 55000000 | C5: =IF(B13=J9,K9,IF(B13=J8,K8,K10)) -> 33700000
A7: FACTURACIÓN | B7: =ENTRADAS!B35 -> Hasta COP 3.000.000.000 | E7: FACTURACIÓN | F7: =ENTRADAS!B35 -> Hasta COP 3.000.000.000 | I7: FACTURACIÓN | J7: =ENTRADAS!B35 -> Hasta COP 3.000.000.000
A8: SECTOR | B8: ABOGADOS | C8: =_xlfn.XLOOKUP(B18,ABOGADOS!$F:$F,ABOGADOS!$E:$E) -> 5100000 | E8: SECTOR | F8: ABOGADOS | G8: =_xlfn.XLOOKUP(F18,ABOGADOS!$F:$F,ABOGADOS!$E:$E) -> 15600000 | I8: SECTOR | J8: ABOGADOS | K8: =_xlfn.XLOOKUP(J18,ABOGADOS!$F:$F,ABOGADOS!$E:$E) -> 34890000
B9: ADMINISTRADORES | C9: =_xlfn.XLOOKUP(B18,'ADMIN PH'!$F:$F,'ADMIN PH'!$E:$E) -> 4200000 | F9: ADMINISTRADORES | G9: =_xlfn.XLOOKUP('busqueda pi'!F18,'ADMIN PH'!$F:$F,'ADMIN PH'!$E:$E) -> 12900000 | J9: ADMINISTRADORES | K9: =_xlfn.XLOOKUP(J18,'ADMIN PH'!$F:$F,'ADMIN PH'!$E:$E) -> 30150000
B10: CONTADORES | C10: =_xlfn.XLOOKUP('busqueda pi'!B18,CONTADORES!$E:$E,CONTADORES!$D:$D) -> 4800000 | F10: CONTADORES | G10: =_xlfn.XLOOKUP('busqueda pi'!F18,CONTADORES!$E:$E,CONTADORES!$D:$D) -> 14900000 | J10: CONTADORES | K10: =_xlfn.XLOOKUP('busqueda pi'!J18,CONTADORES!$E:$E,CONTADORES!$D:$D) -> 33700000
A13: ENTRADA | B13: =ENTRADAS!B39 -> CONTADORES | C13: =VLOOKUP(B13,B8:C10,2,FALSE) -> 4800000
A14: ENTRADA | B14: =B13 -> CONTADORES | C14: =VLOOKUP(B14,F8:G10,2,FALSE) -> 14900000
A15: ENTRADA | B15: =B14 -> CONTADORES | C15: =VLOOKUP(B14,J8:K10,2,FALSE) -> 33700000
B17: LLAVE | F17: LLAVE | J17: LLAVE
B18: =CONCATENATE(B7,B3,A3) -> Hasta COP 3.000.000.00030000000500000000 | F18: =CONCATENATE(B7,B4,A4) -> Hasta COP 3.000.000.000400000002000000000 | J18: =CONCATENATE(B7,B5,A5) -> Hasta COP 3.000.000.000550000005000000000

Sheet ABOGADOS
B4: Limite de facturación
B6: Hasta COP 3.000.000.000
B7: Hasta COP 5.000.000.000
B8: Hasta COP 7.500.000.000
B9: Hasta COP 10.000.000.000
B10: Hasta COP 15.000.000.000
B11: Hasta COP 20.000.000.000
B13: Límite de responsabilidad
B14: 500000000
B15: 1000000000
B16: 1500000000
B17: 2000000000
B18: 3000000000
B19: 4000000000
B20: 5000000000
C33: Hasta COP 3.000.000.000
C34: DEDUCIBLE | D34: LIMITE | E34: PRIMA
B35: Hasta COP 3.000.000.000 | C35: 30000000 | D35: 500000000 | E35: 5100000 | F35: =CONCATENATE(B35,C35,D35) -> Hasta COP 3.000.000.00030000000500000000
B36: Hasta COP 3.000.000.000 | C36: 30000000 | D36: 1000000000 | E36: 8900000 | F36: =CONCATENATE(B36,C36,D36) -> Hasta COP 3.000.000.000300000001000000000
B37: Hasta COP 3.000.000.000 | C37: 30000000 | D37: 1500000000 | E37: 12750000 | F37: =CONCATENATE(B37,C37,D37) -> Hasta COP 3.000.000.000300000001500000000
B38: Hasta COP 3.000.000.000 | C38: 40000000 | D38: 2000000000 | E38: 15600000 | F38: =CONCATENATE(B38,C38,D38) -> Hasta COP 3.000.000.000400000002000000000
B39: Hasta COP 3.000.000.000 | C39: 40000000 | D39: 3000000000 | E39: 22100000 | F39: =CONCATENATE(B39,C39,D39) -> Hasta COP 3.000.000.000400000003000000000
B40: Hasta COP 3.000.000.000 | C40: 45000000 | D40: 4000000000 | E40: 28950000 | F40: =CONCATENATE(B40,C40,D40) -> Hasta COP 3.000.000.000450000004000000000
B41: Hasta COP 3.000.000.000 | C41: 55000000 | D41: 5000000000 | E41: 34890000 | F41: =CONCATENATE(B41,C41,D41) -> Hasta COP 3.000.000.000550000005000000000
B42: Hasta COP 3.000.000.000 | C42: 40000000 | D42: 500000000 | E42: 4500000 | F42: =CONCATENATE(B42,C42,D42) -> Hasta COP 3.000.000.00040000000500000000
B43: Hasta COP 3.000.000.000 | C43: 40000000 | D43: 1000000000 | E43: 8350000 | F43: =CONCATENATE(B43,C43,D43) -> Hasta COP 3.000.000.000400000001000000000
B44: Hasta COP 3.000.000.000 | C44: 40000000 | D44: 1500000000 | E44: 12100000 | F44: =CONCATENATE(B44,C44,D44) -> Hasta COP 3.000.000.000400000001500000000
B45: Hasta COP 3.000.000.000 | C45: 55000000 | D45: 2000000000 | E45: 14600000 | F45: =CONCATENATE(B45,C45,D45) -> Hasta COP 3.000.000.000550000002000000000
B46: Hasta COP 3.000.000.000 | C46: 55000000 | D46: 3000000000 | E46: 20300000 | F46: =CONCATENATE(B46,C46,D46) -> Hasta COP 3.000.000.000550000003000000000
... B118: Hasta COP 20.000.000.000 | C118: 60000000 | D118: 5000000000 | E118: 40212504 | F118: =CONCATENATE(B118,C118,D118) -> Hasta COP 20.000.000.000600000005000000000

Sheet ADMIN PH
B4: Limite de facturación
B6: Hasta COP 3.000.000.000
B7: Hasta COP 5.000.000.000
B8: Hasta COP 7.500.000.000
B9: Hasta COP 10.000.000.000
B10: Hasta COP 15.000.000.000
B11: Hasta COP 20.000.000.000
B13: Límite de responsabilidad
B14: 500000000
B15: 1000000000
B16: 1500000000
B17: 2000000000
B18: 3000000000
B19: 4000000000
B20: 5000000000
B24: LIMITE DE RESPONSABILIDAD (*) | D24: 500000000 | E24: 1000000000 | I24: 4000000000 | J24: 5000000000
B25: FACTURACION TOTAL ANUAL | C25: Hasta COP 3.000.000.000 | D25: 4800000 | E25: 2505891.2 | I25: 6687115.6 | J25: 8221863.5
C26: Hasta COP 5.000.000.000 | D26: 1647285.9 | E26: 2514272.1 | I26: 6800456.6 | J26: 8361217.1
C27: Hasta COP 10.000.000.000 | D27: 1715647.9 | E27: 2522681 | I27: 6915718.5 | J27: 8502932.6
C28: Hasta COP 15.000.000.000 | D28: 1890521.1 | E28: 2531118.1 | I28: 7032934.1 | J28: 8647050.1
C29: Hasta COP 20.000.000.000 | D29: 1938333.3 | E29: 2539583.3 | I29: 7152136.4 | J29: 8793610.3
C37: Hasta COP 3.000.000.000
C38: DEDUCIBLE | D38: LIMITE | E38: PRIMA | F38: llave
B39: Hasta COP 3.000.000.000 | C39: 30000000 | D39: 500000000 | E39: 4200000 | F39: =CONCATENATE(B39,C39,D39) -> Hasta COP 3.000.000.00030000000500000000
B40: Hasta COP 3.000.000.000 | C40: 30000000 | D40: 1000000000 | E40: 7700000 | F40: =CONCATENATE(B40,C40,D40) -> Hasta COP 3.000.000.000300000001000000000
B41: Hasta COP 3.000.000.000 | C41: 30000000 | D41: 1500000000 | E41: 10340000 | F41: =CONCATENATE(B41,C41,D41) -> Hasta COP 3.000.000.000300000001500000000
B42: Hasta COP 3.000.000.000 | C42: 40000000 | D42: 2000000000 | E42: 12900000 | F42: =CONCATENATE(B42,C42,D42) -> Hasta COP 3.000.000.000400000002000000000
B43: Hasta COP 3.000.000.000 | C43: 40000000 | D43: 3000000000 | E43: 18500000 | F43: =CONCATENATE(B43,C43,D43) -> Hasta COP 3.000.000.000400000003000000000
B44: Hasta COP 3.000.000.000 | C44: 45000000 | D44: 4000000000 | E44: 24300000 | F44: =CONCATENATE(B44,C44,D44) -> Hasta COP 3.000.000.000450000004000000000
B45: Hasta COP 3.000.000.000 | C45: 55000000 | D45: 5000000000 | E45: 30150000 | F45: =CONCATENATE(B45,C45,D45) -> Hasta COP 3.000.000.000550000005000000000
B46: Hasta COP 3.000.000.000 | C46: 35000000 | D46: 500000000 | E46: 3700000 | F46: =CONCATENATE(B46,C46,D46) -> Hasta COP 3.000.000.00035000000500000000
B47: Hasta COP 3.000.000.000 | C47: 35000000 | D47: 1000000000 | E47: 7000000 | F47: =CONCATENATE(B47,C47,D47) -> Hasta COP 3.000.000.000350000001000000000
B48: Hasta COP 3.000.000.000 | C48: 35000000 | D48: 1500000000 | E48: 9400000 | F48: =CONCATENATE(B48,C48,D48) -> Hasta COP 3.000.000.000350000001500000000
B49: Hasta COP 3.000.000.000 | C49: 40000000 | D49: 2000000000 | E49: 12000000 | F49: =CONCATENATE(B49,C49,D49) -> Hasta COP 3.000.000.000400000002000000000
B50: Hasta COP 3.000.000.000 | C50: 55000000 | D50: 3000000000 | E50: 17600000 | F50: =CONCATENATE(B50,C50,D50) -> Hasta COP 3.000.000.000550000003000000000
... B122: Hasta COP 20.000.000.000 | C122: 55000000 | D122: 5000000000 | E122: 35122313 | F122: =CONCATENATE(B122,C122,D122) -> Hasta COP 20.000.000.000550000005000000000

Sheet CONTADORES
B7: Hasta COP 3.000.000.000
B8: DEDUCIBLE | C8: LIMITE | D8: PRIMA
A9: Hasta COP 3.000.000.000 | B9: 30000000 | C9: 500000000 | D9: 4800000 | E9: =CONCATENATE(A9,B9,C9) -> Hasta COP 3.000.000.00030000000500000000
A10: Hasta COP 3.000.000.000 | B10: 30000000 | C10: 1000000000 | D10: 8750000 | E10: =CONCATENATE(A10,B10,C10) -> Hasta COP 3.000.000.000300000001000000000
A11: Hasta COP 3.000.000.000 | B11: 30000000 | C11: 1500000000 | D11: 12300000 | E11: =CONCATENATE(A11,B11,C11) -> Hasta COP 3.000.000.000300000001500000000
A12: Hasta COP 3.000.000.000 | B12: 40000000 | C12: 2000000000 | D12: 14900000 | E12: =CONCATENATE(A12,B12,C12) -> Hasta COP 3.000.000.000400000002000000000
A13: Hasta COP 3.000.000.000 | B13: 40000000 | C13: 3000000000 | D13: 21150000 | E13: =CONCATENATE(A13,B13,C13) -> Hasta COP 3.000.000.000400000003000000000
A14: Hasta COP 3.000.000.000 | B14: 45000000 | C14: 4000000000 | D14: 27600000 | E14: =CONCATENATE(A14,B14,C14) -> Hasta COP 3.000.000.000450000004000000000
A15: Hasta COP 3.000.000.000 | B15: 55000000 | C15: 5000000000 | D15: 33700000 | E15: =CONCATENATE(A15,B15,C15) -> Hasta COP 3.000.000.000550000005000000000
A16: Hasta COP 3.000.000.000 | B16: 40000000 | C16: 500000000 | D16: 4100000 | E16: =CONCATENATE(A16,B16,C16) -> Hasta COP 3.000.000.00040000000500000000
A17: Hasta COP 3.000.000.000 | B17: 40000000 | C17: 1000000000 | D17: 8200000 | E17: =CONCATENATE(A17,B17,C17) -> Hasta COP 3.000.000.000400000001000000000
A18: Hasta COP 3.000.000.000 | B18: 40000000 | C18: 1500000000 | D18: 11500000 | E18: =CONCATENATE(A18,B18,C18) -> Hasta COP 3.000.000.000400000001500000000
A19: Hasta COP 3.000.000.000 | B19: 55000000 | C19: 2000000000 | D19: 14000000 | E19: =CONCATENATE(A19,B19,C19) -> Hasta COP 3.000.000.000550000002000000000
A20: Hasta COP 3.000.000.000 | B20: 55000000 | C20: 3000000000 | D20: 19800000 | E20: =CONCATENATE(A20,B20,C20) -> Hasta COP 3.000.000.000550000003000000000
... A92: Hasta COP 20.000.000.000 | B92: 60000000 | C92: 5000000000 | D92: 39448975 | E92: =CONCATENATE(A92,B92,C92) -> Hasta COP 20.000.000.000600000005000000000

Sheet Nuevas Primas CYBER
I2: 0.010022112 | J2: 0.0083814333 | K2: 0.0082538781 | L2: 0.0070733883 | M2: 0.0070486467 | P2: 0.01113568 | Q2: 0.012104 | R2: 0.0136 | T2: 1-100
B3: CONDICIONES: CRIME (Cifras en Pesos Colombianos) | I3: 0.0136 | J3: 0.0126552 | K3: 0.01115075 | L3: 0.011030625 | M3: 0.010327688 | T3: 101-300 | V3: LIMITE | W3: DEDUCIBLE | Z3: COP500.000.000 | AA3: COP1.000.000.000 | AB3: COP1.500.000.000 | AC3: COP2.000.000.000 | AD3: COP3.000.000.000
T4: 301-500 | V4: COP500.000.000 | W4: COP30.000.000 | Z4: COP500.000.000 | AA4: COP1.000.000.000 | AB4: COP1.500.000.000 | AC4: N/A | AD4: N/A
B5: TASA PRINCIPAL | C5: 13.6 | D5: 14.817 | E5: 14.1 | F5: 13.5 | G5: 11.15 | I5: PRIMAS X AGREGADO | V5: COP1.000.000.000 | W5: COP50.000.000 | Z5: COP1.000.000.000 | AA5: COP2.000.000.000 | AB5: COP3.000.000.000
C6: ALTERNATIVAS DE LÍMITE DE RESPONSABILIDAD Por Reclamación y en el Agregado Anual | V6: COP1.500.000.000 | W6: COP60.000.000
A7: 1-100 | B7: FACTURACIÓN ANUAL Hasta COP | C7: 500000000 | D7: 1000000000 | E7: 1500000000 | F7: 2000000000 | G7: 3000000000 | I7: 1-100 | J7: FACTURACIÓN ANUAL Hasta COP | K7: 1000000000 | L7: 2000000000 | M7: 3000000000 | V7: COP2.000.000.000 | W7: COP65.000.000
B8: 15000000000 | C8: 5011056 | D8: 8381433.3 | E8: 12380817 | F8: 14146777 | G8: 21145940 | J8: 15000000000 | K8: 6514372.8 | L8: 11314935 | M8: 17333144 | V8: COP3.000.000.000 | W8: COP70.000.000
B9: 30000000000 | C9: 5567840 | D9: 9860509.8 | E9: 14565667 | F9: 18862369 | G9: 28194587 | J9: 30000000000 | K9: 7238192 | L9: 13311688 | M9: 20391934
B10: 45000000000 | C10: 6052000 | D10: 11600600 | E10: 15332281 | F10: 19855125 | G10: 28917525 | J10: 45000000000 | K10: 7867600 | L10: 15660810 | M10: 21465194 | Z10: 500000000 | AA10: 5500000000
B11: 60000000000 | C11: 6800000 | D11: 12655200 | E11: 16726125 | F11: 22061250 | G11: 30983062 | J11: 60000000000 | K11: 8840000 | L11: 17084520 | M11: 23416575
B12: 80000000000 | C12: N/A | D12: 13001918 | E12: 19299375 | F12: 24975000 | G12: 32613750 | J12: 80000000000 | K12: N/A | L12: 17552589 | M12: 27019125
B13: 100000000000 | C13: N/A | D13: 14817000 | E13: 21150000 | F13: 27000000 | G13: 33450000 | J13: 100000000000 | K13: N/A | L13: 20002950 | M13: 29610000
A17: 101-300 | B17: FACTURACIÓN ANUAL Hasta COP | C17: 500000000 | D17: 1000000000 | E17: 1500000000 | F17: 2000000000 | G17: 3000000000 | I17: 101-300 | J17: FACTURACIÓN ANUAL Hasta COP | K17: 1000000000 | L17: 2000000000 | M17: 3000000000
B18: 15000000000 | C18: 5411940.5 | D18: 9093855.1 | E18: 13495091 | F18: 15561454 | G18: 23471994 | J18: 15000000000 | K18: 7035522.6 | L18: 12276704 | M18: 18893127 | P18: PROPUESTA 2023
B19: 30000000000 | C19: 6013267.2 | D19: 10698653 | E19: 15876577 | F19: 20748606 | G19: 31295991 | J19: 30000000000 | K19: 7817247.4 | L19: 14443182 | M19: 22227208 | Q19: LIMITE | R19: DEDUCIBLE | S19: PRIMA NETA | T19: TASA | U19: TASA MANUAL | V19: PRIMA
B20: 45000000000 | C20: 6536160 | D20: 12586651 | E20: 16712187 | F20: 21840638 | G20: 32098453 | J20: 45000000000 | K20: 8497008 | L20: 16991978 | M20: 23397061 | P20: OPCIÓN 1 | Q20: 500000000 | T20: 0 | V20: 0
B21: 60000000000 | C21: 7344000 | D21: 13730892 | E21: 18231476 | F21: 24267375 | G21: 34391199 | J21: 60000000000 | K21: 9547200 | L21: 18536704 | M21: 25524067 | P21: OPCIÓN 2 | Q21: 1000000000 | S21: 14817000 | T21: 14817 | U21: 61831341000 | V21: 6.1831341e+13
B22: 80000000000 | C22: N/A | D22: 14107080 | E22: 21036319 | F22: 27472500 | G22: 36201262 | J22: 80000000000 | K22: N/A | L22: 19044559 | M22: 29450846 | P22: OPCIÓN 3 | Q22: 1500000000 | S22: 21150000 | T22: 14100 | V22: 0
B23: 100000000000 | C23: N/A | D23: 16076445 | E23: 23053500 | F23: 29700000 | G23: 37129500 | J23: 100000000000 | K23: N/A | L23: 21703201 | M23: 32274900 | P23: OPCIÓN 4 | Q23: 2000000000 | S23: 27000000 | T23: 13500 | V23: 0
P24: OPCIÓN 5 | Q24: 3000000000 | S24: 33450000 | T24: 11150 | V24: 0
A26: 301-500 | B26: FACTURACIÓN ANUAL Hasta COP | C26: 500000000 | D26: 1000000000 | E26: 1500000000 | F26: 2000000000 | G26: 3000000000 | I26: 301-500 | J26: FACTURACIÓN ANUAL Hasta COP | K26: 1000000000 | L26: 2000000000 | M26: 3000000000
B27: 15000000000 | C27: 5682537.5 | D27: 9821363.5 | E27: 14844600 | F27: 17273214 | G27: 26288633 | J27: 15000000000 | K27: 7387298.8 | L27: 13258841 | M27: 20782440
B28: 30000000000 | C28: 6313930.6 | D28: 11554545 | E28: 17464235 | F28: 23030952 | G28: 35051510 | J28: 30000000000 | K28: 8208109.7 | L28: 15598636 | M28: 24449929
B29: 45000000000 | C29: 6862968 | D29: 13593583 | E29: 18383405 | F29: 24243108 | G29: 35950267 | J29: 45000000000 | K29: 8921858.4 | L29: 18351337 | M29: 25736767
B30: 60000000000 | C30: 7711200 | D30: 14829363 | E30: 20054624 | F30: 26936786 | G30: 38518143 | J30: 60000000000 | K30: 10024560 | L30: 20019640 | M30: 28076473
B31: 80000000000 | C31: N/A | D31: 15235647 | E31: 23139951 | F31: 30494475 | G31: 40545414 | J31: 80000000000 | K31: N/A | L31: 20568123 | M31: 32395931
B32: 100000000000 | C32: N/A | D32: 17362561 | E32: 25358850 | F32: 32967000 | G32: 41585040 | J32: 100000000000 | K32: N/A | L32: 23439457 | M32: 35502390
P38: 60000000000 | Q38: 10024560 | R38: 20019640 | S38: 28076473
P39: 80000000000 | Q39: N/A | R39: 20568123 | S39: 32395931
P40: 100000000000 | Q40: N/A | R40: 23439457 | S40: 35502390
A41: EMPLEADOS | B41: INGRESOS | C41: LIMITE EVENTO | D41: LIMITE AGREGADO | E41: CONCATENAR | F41: PRIMA | K41: EMPLEADOS | L41: INGRESOS | M41: LIMITE EVENTO | N41: LIMITE AGREGADO | O41: CONCATENAR | P41: PRIMA
A42: 1-100 | B42: 15000000000 | C42: COP500.000.000 | D42: COP500.000.000 | E42: 1-100-15000000000-COP500.000.000-COP500.000.000 | F42: 5011056 | K42: 1-100 | L42: 15000000000 | M42: COP500.000.000 | N42: COP1.000.000.000 | O42: 1-100-15000000000-COP500.000.000-COP1.000.000.000 | P42: 6514372.8
A43: 1-100 | B43: 15000000000 | C43: COP1.000.000.000 | D43: COP1.000.000.000 | E43: 1-100-15000000000-COP1.000.000.000-COP1.000.000.000 | F43: 8381433.3 | K43: 1-100 | L43: 15000000000 | M43: COP1.000.000.000 | N43: COP2.000.000.000 | O43: 1-100-15000000000-COP1.000.000.000-COP2.000.000.000 | P43: 11314935
A44: 1-100 | B44: 15000000000 | C44: COP1.500.000.000 | D44: COP1.500.000.000 | E44: 1-100-15000000000-COP1.500.000.000-COP1.500.000.000 | F44: 12380817 | K44: 1-100 | L44: 15000000000 | M44: COP1.500.000.000 | N44: COP3.000.000.000 | O44: 1-100-15000000000-COP1.500.000.000-COP3.000.000.000 | P44: 17333144
A45: 1-100 | B45: 15000000000 | C45: COP2.000.000.000 | D45: COP2.000.000.000 | E45: 1-100-15000000000-COP2.000.000.000-COP2.000.000.000 | F45: 14146777 | K45: 1-100 | L45: 30000000000 | M45: COP500.000.000 | N45: COP1.000.000.000 | O45: 1-100-30000000000-COP500.000.000-COP1.000.000.000 | P45: 7238192
A46: 1-100 | B46: 15000000000 | C46: COP3.000.000.000 | D46: COP3.000.000.000 | E46: 1-100-15000000000-COP3.000.000.000-COP3.000.000.000 | F46: 21145940 | K46: 1-100 | L46: 30000000000 | M46: COP1.000.000.000 | N46: COP2.000.000.000 | O46: 1-100-30000000000-COP1.000.000.000-COP2.000.000.000 | P46: 13311688
A47: 1-100 | B47: 30000000000 | C47: COP500.000.000 | D47: COP500.000.000 | E47: 1-100-30000000000-COP500.000.000-COP500.000.000 | F47: 5567840 | K47: 1-100 | L47: 30000000000 | M47: COP1.500.000.000 | N47: COP3.000.000.000 | O47: 1-100-30000000000-COP1.500.000.000-COP3.000.000.000 | P47: 20391934
A48: 1-100 | B48: 30000000000 | C48: COP1.000.000.000 | D48: COP1.000.000.000 | E48: 1-100-30000000000-COP1.000.000.000-COP1.000.000.000 | F48: 9860509.8 | K48: 1-100 | L48: 45000000000 | M48: COP500.000.000 | N48: COP1.000.000.000 | O48: 1-100-45000000000-COP500.000.000-COP1.000.000.000 | P48: 7867600
A49: 1-100 | B49: 30000000000 | C49: COP1.500.000.000 | D49: COP1.500.000.000 | E49: 1-100-30000000000-COP1.500.000.000-COP1.500.000.000 | F49: 14565667 | K49: 1-100 | L49: 45000000000 | M49: COP1.000.000.000 | N49: COP2.000.000.000 | O49: 1-100-45000000000-COP1.000.000.000-COP2.000.000.000 | P49: 15660810
A50: 1-100 | B50: 30000000000 | C50: COP2.000.000.000 | D50: COP2.000.000.000 | E50: 1-100-30000000000-COP2.000.000.000-COP2.000.000.000 | F50: 18862369 | K50: 1-100 | L50: 45000000000 | M50: COP1.500.000.000 | N50: COP3.000.000.000 | O50: 1-100-45000000000-COP1.500.000.000-COP3.000.000.000 | P50: 21465194
...

Sheet TasasINFIDELIDAD EMPLEADOS
A1: CALCULO PRIMA HASTA COP15.000.000.000 Y 100 EMPLEADOS (NUEVO FF INGRESOS HASTA 30.000.000.000) | F1: 0-100 | G1: 101-300 | H1: 301-500
A3: PROPUESTA ECONOMICA
B4: LIMITE | C4: DEDUCIBLE | D4: PRIMA NETA | E4: TASA | F4: CALCULO PRIMA HASTA COP30.000.000.000 Y 100 EMPLEADOS | G4: TASA | H4: CALCULO PRIMA HASTA COP45.000.000.000 Y 100 EMPLEADOS | I4: TASA | J4: CALCULO PRIMA HASTA COP60.000.000.000 Y 100 EMPLEADOS | K4: TASA | L4: CALCULO PRIMA HASTA COP100.000.000.000 Y 100 EMPLEADOS | M4: TASA | N4: CALCULO PRIMA HASTA COP30.000.000.000,(101-300) EMPLEADOS | O4: TASA | P4: CALCULO PRIMA HASTA COP45.000.000.000 (101-300) EMPLEADOS | Q4: TASA | R4: CALCULO PRIMA HASTA COP60.000.000.000 (101-300) EMPLEADOS | S4: TASA | T4: CALCULO PRIMA HASTA COP100.000.000.000 (101-300) EMPLEADOS | U4: TASA | V4: CALCULO PRIMA HASTA COP30.000.000.000,(301-500) EMPLEADOS | W4: TASA | X4: CALCULO PRIMA HASTA COP45.000.000.000 (301-500) EMPLEADOS | Y4: TASA | Z4: CALCULO PRIMA HASTA COP60.000.000.000 (301-500) EMPLEADOS | AA4: TASA | AB4: CALCULO PRIMA HASTA COP100.000.000.000 (301-500) EMPLEADOS | AC4: TASA
A5: ALTERNATIVA 1 | B5: 500000000 | C5: 30000000 | D5: 4650000 | E5: 9300 | F5: 5115000 | G5: 10230 | H5: 5473050 | I5: 10946.1 | J5: 5746702.5 | K5: 11493.405 | L5: 6034037.6 | M5: 12068.075 | N5: 5473050 | O5: 10946.1 | P5: 5801433 | Q5: 11602.866 | R5: 5746703.9 | S5: 11493.408 | T5: 8447652.7 | U5: 16895.305 | V5: 6348738 | W5: 12697.476 | X5: 6671647.9 | Y5: 13343.296 | Z5: 7183379.9 | AA5: 14366.76 | AB5: 8701082.3 | AC5: 17402.165
A6: ALTERNATIVA 2 | B6: 1000000000 | C6: 50000000 | D6: 7866000 | E6: 7866 | F6: 8652600 | G6: 8652.6 | H6: 9258282 | I6: 9258.282 | J6: 9721196.1 | K6: 9721.1961 | L6: 10207256 | M6: 10207.256 | N6: 9258282 | O6: 9258.282 | P6: 9813778.9 | Q6: 9813.7789 | R6: 9721197.5 | S6: 9721.1975 | T6: 14290158 | U6: 14290.158 | V6: 10739607 | W6: 10739.607 | X6: 11285846 | Y6: 11285.846 | Z6: 12151497 | AA6: 12151.497 | AB6: 14718863 | AC6: 14718.863
A7: ALTERNATIVA 3 | B7: 1500000000 | C7: 60000000 | D7: 11307000 | E7: 7538 | F7: 12437700 | G7: 8291.8 | H7: 13308339 | I7: 8872.226 | J7: 13973756 | K7: 9315.8373 | L7: 14672444 | M7: 9781.6292 | N7: 13308339 | O7: 8872.226 | P7: 14106839 | Q7: 9404.5596 | R7: 13973757 | S7: 9315.8382 | T7: 20541421 | U7: 13694.281 | V7: 15437673 | W7: 10291.782 | X7: 16222865 | Y7: 10815.243 | Z7: 17467197 | AA7: 11644.798 | AB7: 21157664 | AC7: 14105.109
A8: ALTERNATIVA 4 | B8: 2000000000 | C8: 65000000 | D8: 15170000 | E8: 7585 | F8: 16687000 | G8: 8343.5 | H8: 17855090 | I8: 8927.545 | J8: 18747845 | K8: 9373.9223 | L8: 19685237 | M8: 9842.6184 | N8: 17855090 | O8: 8927.545 | P8: 18926395 | Q8: 9463.1977 | R8: 18747846 | S8: 9373.923 | T8: 27559331 | U8: 13779.666 | V8: 20711904 | W8: 10355.952 | X8: 21765355 | Y8: 10882.677 | Z8: 23434807 | AA8: 11717.404 | AB8: 28386111 | AC8: 14193.056
A9: ALTERNATIVA 5 | B9: 3000000000 | C9: 70000000 | D9: 22000000 | E9: 7333.3333 | F9: 24200000 | G9: 8066.6667 | H9: 25894000 | I9: 8631.3333 | J9: 27188700 | K9: 9062.9 | L9: 28548135 | M9: 9516.045 | N9: 25894000 | O9: 8631.3333 | P9: 27447640 | Q9: 9149.2133 | R9: 27188701 | S9: 9062.9005 | T9: 39967389 | U9: 13322.463 | V9: 30037040 | W9: 10012.347 | X9: 31564786 | Y9: 10521.595 | Z9: 33985877 | AA9: 11328.626 | AB9: 41965758 | AC9: 13988.586
A11: AGREGADO
B12: LIMITE | C12: DEDUCIBLE | D12: PRIMA NETA | E12: TASA | F12: CALCULO PRIMA HASTA COP30.000.000.000 Y 100 EMPLEADOS | G12: TASA | H12: CALCULO PRIMA HASTA COP45.000.000.000 Y 100 EMPLEADOS | I12: TASA | J12: CALCULO PRIMA HASTA COP60.000.000.000 Y 100 EMPLEADOS | K12: TASA | L12: CALCULO PRIMA HASTA COP100.000.000.000 Y 100 EMPLEADOS | M12: TASA | N12: CALCULO PRIMA HASTA COP30.000.000.000,(101-300) EMPLEADOS | O12: TASA | P12: CALCULO PRIMA HASTA COP45.000.000.000 (101-300) EMPLEADOS | Q12: TASA | R12: CALCULO PRIMA HASTA COP60.000.000.000 (101-300) EMPLEADOS | S12: TASA | T12: CALCULO PRIMA HASTA COP100.000.000.000 (101-300) EMPLEADOS | U12: TASA | V12: CALCULO PRIMA HASTA COP30.000.000.000,(301-500) EMPLEADOS | W12: TASA | X12: CALCULO PRIMA HASTA COP45.000.000.000 (301-500) EMPLEADOS | Y12: TASA | Z12: CALCULO PRIMA HASTA COP60.000.000.000 (301-500) EMPLEADOS | AA12: TASA | AB12: CALCULO PRIMA HASTA COP100.000.000.000 (301-500) EMPLEADOS | AC12: TASA
A13: ALTERNATIVA 1 | B13: 1000000000 | C13: 30000000 | D13: 5347500 | E13: 10695 | F13: 5882250 | G13: 11764.5 | H13: 6294007.5 | I13: 12588.015 | J13: 6608707.9 | K13: 13217.416 | L13: 6939143.3 | M13: 13878.287 | N13: 6294007.5 | O13: 12588.015 | P13: 6671648 | Q13: 13343.296 | R13: 6608709.3 | S13: 13217.419 | T13: 9714800.6 | U13: 19429.601 | V13: 6671648 | W13: 13343.296 | X13: 7005230.3 | Y13: 14010.461 | Z13: 6806970.6 | AA13: 13613.941 | AB13: 10006245 | AC13: 20012.489
A14: ALTERNATIVA 2 | B14: 2000000000 | C14: 50000000 | D14: 9045900 | E14: 9045.9 | F14: 9950490 | G14: 9950.49 | H14: 10647024 | I14: 10647.024 | J14: 11179376 | K14: 11179.376 | L14: 11738344 | M14: 11738.344 | N14: 10647024 | O14: 10647.024 | P14: 11285846 | Q14: 11285.846 | R14: 11179377 | S14: 11179.377 | T14: 16433682 | U14: 16433.682 | V14: 11285846 | W14: 11285.846 | X14: 11850138 | Y14: 11850.138 | Z14: 11514758 | AA14: 11514.758 | AB14: 16926692 | AC14: 16926.692
A15: ALTERNATIVA 3 | B15: 3000000000 | C15: 70000000 | D15: 13003050 | E15: 8668.7 | F15: 14303355 | G15: 9535.57 | H15: 15304590 | I15: 10203.06 | J15: 16069819 | K15: 10713.213 | L15: 16873310 | M15: 11248.874 | N15: 15304590 | O15: 10203.06 | P15: 16222865 | Q15: 10815.243 | R15: 16069821 | S15: 10713.214 | T15: 23622634 | U15: 15748.423 | V15: 16222865 | W15: 10815.243 | X15: 17034009 | Y15: 11356.006 | Z15: 16551915 | AA15: 11034.61 | AB15: 24331313 | AC15: 16220.876
A25: ALTERNATIVA 2 / ALTERNATIVA I | B25: 1 | C25: 0.66666667 | D25: 0.6916129 | E25: -0.15419355
A26: ALTERNATIVA 3 / ALTERNATIVA I | B26: 2 | C26: 1 | D26: 1.4316129 | E26: -0.18946237
A27: ALTERNATIVA 4 / ALTERNATIVA I | B27: 3 | C27: 1.1666667 | D27: 2.2623656 | E27: -0.1844086
A30: CALCULO PRIMA HASTA COP30.000.000.000 Y 100 EMPLEADOS | G30: CALCULO PRIMA HASTA COP30.000.000.000 Y 300 EMPLEADOS ( (NUEVO FF INGRESOS HASTA 45.000.000.000)
A32: PROPUESTA ECONOMICA | G32: PROPUESTA ECONOMICA
B33: LIMITE | C33: DEDUCIBLE | D33: PRIMA NETA | E33: TASA | H33: LIMITE | I33: DEDUCIBLE | J33: PRIMA NETA | K33: TASA
A34: ALTERNATIVA 1 | B34: 500000000 | C34: 30000000 | D34: 4650000 | E34: 9300 | G34: ALTERNATIVA 1 | H34: 500000000 | I34: 50000000 | J34: 7990000 | K34: 15980
A35: ALTERNATIVA 2 | B35: 1000000000 | C35: 60000000 | D35: 7866000 | E35: 7866 | G35: ALTERNATIVA 2 | H35: 1000000000 | I35: 60000000 | J35: 13798000 | K35: 13798
A36: ALTERNATIVA 3 | B36: 1500000000 | C36: 75000000 | D36: 11307000 | E36: 7538 | G36: ALTERNATIVA 3 | H36: 1500000000 | I36: 75000000 | J36: 19835000 | K36: 13223.333
A37: ALTERNATIVA 4 | B37: 2000000000 | C37: 90000000 | D37: 15170000 | E37: 7585 | G37: ALTERNATIVA 3 | H37: 2000000000 | I37: 90000000 | J37: 26612000 | K37: 13306
A40: ALTERNATIVA 2 / ALTERNATIVA I | B40: 1 | C40: 1 | D40: 0.6916129 | E40: -0.15419355 | G40: ALTERNATIVA 2 / ALTERNATIVA I | H40: 1 | I40: 0.2 | J40: 0.72690864 | K40: -0.13654568
A41: ALTERNATIVA 3 / ALTERNATIVA I | B41: 2 | C41: 1.5 | D41: 1.4316129 | E41: -0.18946237 | G41: ALTERNATIVA 3 / ALTERNATIVA I | H41: 2 | I41: 0.5 | J41: 1.4824781 | K41: -0.1725073
A42: ALTERNATIVA 4 / ALTERNATIVA I | B42: 3 | C42: 2 | D42: 2.2623656 | E42: -0.1844086 | G42: ALTERNATIVA 4 / ALTERNATIVA I | H42: 3 | I42: 0.8 | J42: 2.3306633 | K42: -0.16733417
Y44: ACTUAL | AD44: PROPUESTA
A45: CALCULO PRIMA HASTA COP45.000.000.000 Y 100 EMPLEADOS | G45: CALCULO PRIMA HASTA COP40.000.000.000 Y 300 EMPLEADOS ( (NUEVO FF INGRESOS HASTA 70.000.000.000) | N45: CALCULO PRIMA HASTA COP40.000.000.000 Y 300 EMPLEADOS (NUEVO FF RANGO DE HASTA 60,000,000 Y 300 EMPLEADOS | Y45: CALCULO PRIMA HASTA COP40.000.000.000 Y 500 EMPLEADOS | AD45: CALCULO PRIMA HASTA COP40.000.000.000 Y 500 EMPLEADOS
A47: PROPUESTA ECONOMICA | G47: PROPUESTA ECONOMICA | N47: PROPUESTA ECONOMICA | Y47: PROPUESTA ECONOMICA | AD47: PROPUESTA ECONOMICA
B48: LIMITE | C48: DEDUCIBLE | D48: PRIMA NETA | E48: TASA | H48: LIMITE | I48: DEDUCIBLE | J48: PRIMA NETA | K48: TASA | O48: LIMITE | P48: DEDUCIBLE | Q48: PRIMA NETA | R48: TASA | Z48: LIMITE | AA48: DEDUCIBLE | AB48: PRIMA NETA | AC48: TASA | AE48: LIMITE | AF48: DEDUCIBLE | AG48: PRIMA NETA | AH48: TASA
A49: ALTERNATIVA 1 | B49: 500000000 | C49: 50000000 | D49: 5016000 | E49: 10032 | G49: ALTERNATIVA 1 | H49: 500000000 | I49: 50000000 | J49: 8799000 | K49: 17598 | N49: ALTERNATIVA 1 | O49: 500000000 | P49: 45000000 | Q49: 6775230 | R49: 13550.46 | S49: -0.23 | Y49: ALTERNATIVA 1 | Z49: 500000000 | AA49: 50000000 | AB49: 12498000 | AC49: 24996 | AD49: ALTERNATIVA 1 | AE49: 500000000 | AF49: 45000000 | AG49: 9998400 | AH49: 19996.8 | AI49: -0.2
A50: ALTERNATIVA 2 | B50: 1000000000 | C50: 60000000 | D50: 8653000 | E50: 8653 | G50: ALTERNATIVA 2 | H50: 1000000000 | I50: 60000000 | J50: 15178000 | K50: 15178 | N50: ALTERNATIVA 2 | O50: 1000000000 | P50: 55000000 | Q50: 11838840 | R50: 11838.84 | S50: -0.22 | Y50: ALTERNATIVA 2 | Z50: 1000000000 | AA50: 60000000 | AB50: 21559000 | AC50: 21559 | AD50: ALTERNATIVA 2 | AE50: 1000000000 | AF50: 55000000 | AG50: 17786175 | AH50: 17786.175 | AI50: -0.175
A51: ALTERNATIVA 3 | B51: 1500000000 | C51: 75000000 | D51: 12439000 | E51: 8292.6667 | G51: ALTERNATIVA 3 | H51: 1500000000 | I51: 75000000 | J51: 21818000 | K51: 14545.333 | N51: ALTERNATIVA 3 | O51: 1500000000 | P51: 70000000 | Q51: 17018040 | R51: 11345.36 | S51: -0.22 | Y51: ALTERNATIVA 3 | Z51: 1500000000 | AA51: 75000000 | AB51: 30991000 | AC51: 20660.667 | AD51: ALTERNATIVA 3 | AE51: 1500000000 | AF51: 70000000 | AG51: 25567575 | AH51: 17045.05 | AI51: -0.175
A52: ALTERNATIVA 4 | B52: 2000000000 | C52: 90000000 | D52: 16689000 | E52: 8344.5 | G52: ALTERNATIVA 3 | H52: 2000000000 | I52: 90000000 | J52: 29272000 | K52: 14636 | N52: ALTERNATIVA 3 | O52: 2000000000 | P52: 80000000 | Q52: 21954000 | R52: 10977 | S52: -0.25 | Y52: ALTERNATIVA 3 | Z52: 2000000000 | AA52: 90000000 | AB52: 41580000 | AC52: 20790 | AD52: ALTERNATIVA 3 | AE52: 2000000000 | AF52: 80000000 | AG52: 33264000 | AH52: 16632 | AI52: -0.2
A55: ALTERNATIVA 2 / ALTERNATIVA I | B55: 1 | C55: 0.2 | D55: 0.72507974 | E55: -0.13746013 | G55: ALTERNATIVA 2 / ALTERNATIVA I | H55: 1 | I55: 0.2 | J55: 0.72496875 | K55: -0.13751563 | N55: ALTERNATIVA 2 / ALTERNATIVA I | O55: 1 | P55: 0.22222222 | Q55: 0.74737094 | R55: -0.12631453 | Y55: ALTERNATIVA 2 / ALTERNATIVA I | Z55: 1 | AA55: 0.2 | AB55: 0.724996 | AC55: -0.137502 | AD55: ALTERNATIVA 2 / ALTERNATIVA I | AE55: 1 | AF55: 0.22222222 | AG55: 0.77890212 | AH55: -0.11054894
A56: ALTERNATIVA 3 / ALTERNATIVA I | B56: 2 | C56: 0.5 | D56: 1.4798644 | E56: -0.17337852 | G56: ALTERNATIVA 3 / ALTERNATIVA I | H56: 2 | I56: 0.5 | J56: 1.4796 | K56: -0.17346668 | N56: ALTERNATIVA 3 / ALTERNATIVA I | O56: 2 | P56: 0.55555556 | Q56: 1.5118026 | R56: -0.16273248 | Y56: ALTERNATIVA 3 / ALTERNATIVA I | Z56: 2 | AA56: 0.5 | AB56: 1.4796767 | AC56: -0.17344108 | AD56: ALTERNATIVA 3 / ALTERNATIVA I | AE56: 2 | AF56: 0.55555556 | AG56: 1.5571666 | AH56: -0.14761112
A57: ALTERNATIVA 4 / ALTERNATIVA I | B57: 3 | C57: 0.8 | D57: 2.3271531 | E57: -0.16821172 | G57: ALTERNATIVA 4 / ALTERNATIVA I | H57: 3 | I57: 0.8 | J57: 2.3267417 | K57: -0.16831458 | N57: ALTERNATIVA 4 / ALTERNATIVA I | O57: 3 | P57: 0.77777778 | Q57: 2.2403328 | R57: -0.1899168 | Y57: ALTERNATIVA 4 / ALTERNATIVA I | Z57: 3 | AA57: 0.8 | AB57: 2.3269323 | AC57: -0.16826692 | AD57: ALTERNATIVA 4 / ALTERNATIVA I | AE57: 3 | AF57: 0.77777778 | AG57: 2.3269323 | AH57: -0.16826692
A60: CALCULO PRIMA HASTA COP60.000.000.000 Y 100 EMPLEADOS | G60: CALCULO PRIMA HASTA COP60.000.000.000 Y 300 EMPLEADOS ( (NUEVO FF INGRESOS HASTA 100.000.000.000) | N60: CALCULO PRIMA HASTA COP60.000.000.000 Y 300 EMPLEADOS | Y60: CALCULO PRIMA HASTA COP40.000.000.000 Y 500 EMPLEADOS | AD60: CALCULO PRIMA HASTA COP60.000.000.000 Y 500 EMPLEADOS
A62: PROPUESTA ECONOMICA | G62: PROPUESTA ECONOMICA | N62: PROPUESTA ECONOMICA | Y62: PROPUESTA ECONOMICA | AD62: PROPUESTA ECONOMICA
B63: LIMITE | C63: DEDUCIBLE | D63: PRIMA NETA | E63: TASA | H63: LIMITE | I63: DEDUCIBLE | J63: PRIMA NETA | K63: TASA | O63: LIMITE | P63: DEDUCIBLE | Q63: PRIMA NETA | R63: TASA | Z63: LIMITE | AA63: DEDUCIBLE | AB63: PRIMA NETA | AC63: TASA | AE63: LIMITE | AF63: DEDUCIBLE | AG63: PRIMA NETA | AH63: TASA
...

Sheet Configuracion INFIDELIDAD EMPLE
J1: Se otorga | L1: Otros
H2: 15000000000 | J2: No se otorga | L2: Copropiedades
H3: 30000000000 | I3: 0-100 | L3: Construcción
H4: 45000000000 | I4: 101-200 | L4: Educación, escolarización y atención a la infancia
H5: 60000000000 | I5: 201-300 | L5: Centros Comerciales
B6: Hasta COP 15.000.000.000 | C6: 1 | D6: 1 a 100 | H6: 100000000000 | I6: 301-500 | L6: Servicios de transporte y almacenamiento
B7: Hasta COP 30.000.000.000 | C7: 2 | D7: 1 a 100 | E7: 101 a 300 | L7: Industria manufacturera (maquinaria, equipos, tecnología)
B8: Hasta COP 45.000.000.000 | C8: 3 | D8: 1 a 100 | E8: 101 a 300 | F8: 301 a 500 | L8: Hoteles, alojamiento y hostelería
B9: Hasta COP 60.000.000.000 | C9: 4 | D9: 1 a 100 | E9: 101 a 300 | F9: 301 a 500
B12: LÍMITE POR EVENTO | D12: AGREGADO ANUAL
B14: 500000000 | C14: 1 | D14: 500000000 | E14: 1000000000
B15: 1000000000 | C15: 2 | D15: 1000000000 | E15: 2000000000
B16: 1500000000 | C16: 3 | D16: 1500000000 | E16: 3000000000
B17: 2000000000 | C17: 4 | D17: 2000000000
B20: LÍMITE POR EVENTO
B21: 500000000 | C21: 500000000 | D21: 500000000_500000000 | E21: 50000000
B22: 500000000 | C22: 1000000000 | D22: 500000000_1000000000 | E22: 50000000
B23: 1000000000 | C23: 1000000000 | D23: 1000000000_1000000000 | E23: 60000000
B24: 1000000000 | C24: 2000000000 | D24: 1000000000_2000000000 | E24: 60000000
B25: 1500000000 | C25: 1500000000 | D25: 1500000000_1500000000 | E25: 75000000
B26: 1500000000 | C26: 3000000000 | D26: 1500000000_3000000000 | E26: 75000000
B27: 2000000000 | C27: 2000000000 | D27: 2000000000_2000000000 | E27: 90000000
B31: PRIMAS Y DEDUCIBLES OFERTA FAST FLOW - V5 03.04.2024
C33: LÍMITE POR EVENTO | F33: 500000000 | G33: 500000000 | H33: 1000000000 | I33: 1000000000 | J33: 1500000000 | K33: 1500000000 | L33: 2000000000
C34: AGREGADO ANUAL | F34: 500000000 | G34: 1000000000 | H34: 1000000000 | I34: 2000000000 | J34: 1500000000 | K34: 3000000000 | L34: 2000000000
B35: FACTURACIÓN | C35: EMPLEADOS | F35: 500000000_500000000 | G35: 500000000_1000000000 | H35: 1000000000_1000000000 | I35: 1000000000_2000000000 | J35: 1500000000_1500000000 | K35: 1500000000_3000000000 | L35: 2000000000_2000000000
F36: 1 | G36: 2 | H36: 3 | I36: 4 | J36: 5 | K36: 6 | L36: 7
B37: Hasta COP 15.000.000.000 | C37: 1 a 100 | D37: Hasta COP 15.000.000.000_1 a 100 | E37: 1 | F37: 3800000 | G37: 4370000 | H37: 6555000 | I37: 7538250 | J37: 9423000 | K37: 10836450 | L37: 12643000
B38: Hasta COP 30.000.000.000 | C38: 1 a 100 | D38: Hasta COP 30.000.000.000_1 a 100 | E38: 2 | F38: 4560000 | G38: 5244000 | H38: 7866000 | I38: 9045900 | J38: 11307000 | K38: 13003050 | L38: 15170000
B39: Hasta COP 30.000.000.000 | C39: 101 a 300 | D39: Hasta COP 30.000.000.000_101 a 300 | E39: 3 | F39: 7999000 | G39: 9198850 | H39: 13798000 | I39: 15867700 | J39: 19835000 | K39: 22810250 | L39: 26612000
B40: Hasta COP 45.000.000.000 | C40: 1 a 100 | D40: Hasta COP 45.000.000.000_1 a 100 | E40: 4 | F40: 5016000 | G40: 5768400 | H40: 8653000 | I40: 9950950 | J40: 12439000 | K40: 14304850 | L40: 16689000
B41: Hasta COP 45.000.000.000 | C41: 101 a 300 | D41: Hasta COP 45.000.000.000_101 a 300 | E41: 5 | F41: 8799000 | G41: 10118850 | H41: 15178000 | I41: 17454700 | J41: 21818000 | K41: 25090700 | L41: 29272000
B42: Hasta COP 45.000.000.000 | C42: 301 a 500 | D42: Hasta COP 45.000.000.000_301 a 500 | E42: 6 | F42: 12498000 | G42: 14372700 | H42: 21559000 | I42: 24792850 | J42: 30991000 | K42: 35639650 | L42: 41580000
B43: Hasta COP 60.000.000.000 | C43: 1 a 100 | D43: Hasta COP 60.000.000.000_1 a 100 | E43: 7 | F43: 5267000 | G43: 6057050 | H43: 9086000 | I43: 10448900 | J43: 13061000 | K43: 15020150 | L43: 17524000
B44: Hasta COP 60.000.000.000 | C44: 101 a 300 | D44: Hasta COP 60.000.000.000_101 a 300 | E44: 8 | F44: 9239000 | G44: 10624850 | H44: 15937000 | I44: 18327550 | J44: 22909000 | K44: 26345350 | L44: 30736000
B45: Hasta COP 60.000.000.000 | C45: 301 a 500 | D45: Hasta COP 60.000.000.000_301 a 500 | E45: 9 | F45: 13123000 | G45: 15091450 | H45: 22637000 | I45: 26032550 | J45: 32541000 | K45: 37422150 | L45: 43659000
B48: Nuevo
B49: Renovación | G49: 570000
F50: 4560000 | G50: -684000 | H50: 1.15
H51: 1.15

Sheet CALCULOS CYBER
A1: INFIDELIDAD DE EMPLEADOS
A2: PRIMA ANUAL COMERCIAL (BRUTA) ANTES DE IMPUESTOS | B2: DEDUCIBLE | C2: PRIMA
A3: ALTERNATIVA 1 | B3: =IFERROR(+_xlfn.XLOOKUP(D3,PRIMAS!$A$57:$A$92,PRIMAS!$D$57:$D$92,0),"-") -> 50000000 | C3: =IFERROR(+_xlfn.XLOOKUP(D3,PRIMAS!$A$18:$A$53,PRIMAS!$D$18:$D$53,0),"-") -> 8563362.5 | D3: =CONCATENATE(ENTRADAS!B27,"-",ENTRADAS!B28) -> 45000000000-1000000000
A4: ALTERNATIVA 2 | B4: =IFERROR(+_xlfn.XLOOKUP(D4,PRIMAS!$A$57:$A$92,PRIMAS!$D$57:$D$92,0),"-") -> 50000000 | C4: =IFERROR(+_xlfn.XLOOKUP(D4,PRIMAS!$A$18:$A$53,PRIMAS!$D$18:$D$53,0),"-") -> 8563362.5 | D4: =CONCATENATE(ENTRADAS!B27,"-",ENTRADAS!B29) -> 45000000000-1000000000
A5: ALTERNATIVA 3 | B5: =IFERROR(+_xlfn.XLOOKUP(D5,PRIMAS!$A$57:$A$92,PRIMAS!$D$57:$D$92,0),"-") -> 50000000 | C5: =IFERROR(+_xlfn.XLOOKUP(D5,PRIMAS!$A$18:$A$53,PRIMAS!$D$18:$D$53,0),"-") -> 8563362.5 | D5: =CONCATENATE(ENTRADAS!B27,"-",ENTRADAS!B30) -> 45000000000-1000000000
A7: PRIMA NOTA DE COBERTURA | B7: DEDUCIBLE | C7: PRIMA
A8: 1 | B8: =B3 -> 50000000 | C8: =C3 -> 8563362.5
A9: 2 | B9: =B4 -> 50000000 | C9: =C4 -> 8563362.5
A10: 3 | B10: =B5 -> 50000000 | C10: =C5 -> 8563362.5

Sheet PRIMAS
C3: CONDICIONES: CYBER (Cifras en Pesos Colombianos)
C5: TASA PRINCIPAL | D5: 10.89 | E5: 12.915 | F5: 10.461 | G5: 9.7 | H5: 8.7 | I5: 8
D6: ALTERNATIVAS DE LÍMITE DE RESPONSABILIDAD Por Reclamación y en el Agregado Anual
C7: FACTURACIÓN ANUAL Hasta COP | D7: 500000000 | E7: 1000000000 | F7: 2000000000 | G7: 3000000000 | H7: 4000000000 | I7: 5000000000
C8: 15000000000 | D8: =IFERROR(+D9+D9*($C$9/$C$8-1)*-0.12,0) -> 3499784.6 | E8: =IFERROR(+E9+E9*($C$9/$C$8-1)*-0.105,0) -> 6131367.5 | F8: =IFERROR(+F9+F9*($C$9/$C$8-1)*-0.1,0) -> 11313768 | G8: =IFERROR(+G9+G9*($C$9/$C$8-1)*-0.1,0) -> 15814600 | H8: N/A | I8: N/A
C9: 30000000000 | D9: =IFERROR(+D10+D10*($C$9/$C$8-1)*-0.12,0) -> 3977028 | E9: =IFERROR(+E10+E10*($C$10/$C$9-1)*-0.4,0) -> 6850690 | F9: =IFERROR(+F10+F10*($C$10/$C$9-1)*-0.3,0) -> 12570853 | G9: =IFERROR(+G10+G10*($C$10/$C$9-1)*-0.25,0) -> 17571777 | H9: N/A | I9: N/A
C10: 45000000000 | D10: =IFERROR(+D11+D11*($C$9/$C$8-1)*-0.17,0) -> 4519350 | E10: =IFERROR(+E11+E11*($C$11/$C$10-1)*-0.25,0) -> 8563362.5 | F10: =IFERROR(+F11+F11*($C$11/$C$10-1)*-0.5,0) -> 14789239 | G10: =IFERROR(+G11+G11*($C$11/$C$10-1)*-0.5,0) -> 20082031 | H10: N/A | I10: N/A
C11: 60000000000 | D11: =+$D$7*D5/1000 -> 5445000 | E11: =IFERROR(+E12+E12*($C$12/$C$11-1)*-0.52,0) -> 9341850 | F11: =IFERROR(+F12+F12*($C$12/$C$11-1)*-0.3,0) -> 17747086 | G11: =IFERROR(+G12+G12*($C$12/$C$11-1)*-0.35,0) -> 24098437 | H11: =IFERROR(+H12+H12*($C$12/$C$11-1)*-0.29,0) -> 29628430 | I11: =IFERROR(+I12+I12*($C$12/$C$11-1)*-0.39,0) -> 33669000
C12: 80000000000 | D12: N/A | E12: =IFERROR(+E13+E13*($C$13/$C$12-1)*-0.5,0) -> 11300625 | F12: =IFERROR(+F13+F13*($C$13/$C$12-1)*-0.23,0) -> 19718985 | G12: =IFERROR(+G13+G13*($C$13/$C$12-1)*-0.25,0) -> 27281250 | H12: =IFERROR(+H13+H13*($C$13/$C$12-1)*-0.23,0) -> 32799000 | I12: =IFERROR(+I13+I13*($C$13/$C$12-1)*-0.13,0) -> 38700000
C13: 100000000000 | D13: N/A | E13: =+$E$7*E5/1000 -> 12915000 | F13: =+$F$7*F5/1000 -> 20922000 | G13: =+$G$7*G5/1000 -> 29100000 | H13: =+$H$7*H5/1000 -> 34800000 | I13: =+$I$7*I5/1000 -> 40000000
A17: PRIMAS
A18: =+CONCATENATE(B18,"-",C18) -> 15000000000-500000000 | B18: =+$C$8 -> 15000000000 | C18: =+$D$7 -> 500000000 | D18: =+D8 -> 3499784.6
A19: =+CONCATENATE(B19,"-",C19) -> 15000000000-1000000000 | B19: =+$C$8 -> 15000000000 | C19: =+$E$7 -> 1000000000 | D19: =+E8 -> 6131367.5
A20: =+CONCATENATE(B20,"-",C20) -> 15000000000-2000000000 | B20: =+$C$8 -> 15000000000 | C20: =+$F$7 -> 2000000000 | D20: =+F8 -> 11313768
A21: =+CONCATENATE(B21,"-",C21) -> 15000000000-3000000000 | B21: =+$C$8 -> 15000000000 | C21: =+$G$7 -> 3000000000 | D21: =+G8 -> 15814600
A22: =+CONCATENATE(B22,"-",C22) -> 15000000000-4000000000 | B22: =+$C$8 -> 15000000000 | C22: =+$H$7 -> 4000000000 | D22: =+H8 -> N/A
A23: =+CONCATENATE(B23,"-",C23) -> 15000000000-5000000000 | B23: =+$C$8 -> 15000000000 | C23: =+$I$7 -> 5000000000 | D23: =+I8 -> N/A
A24: =+CONCATENATE(B24,"-",C24) -> 30000000000-500000000 | B24: =+$C$9 -> 30000000000 | C24: =+$D$7 -> 500000000 | D24: =+D9 -> 3977028
A25: =+CONCATENATE(B25,"-",C25) -> 30000000000-1000000000 | B25: =+$C$9 -> 30000000000 | C25: =+$E$7 -> 1000000000 | D25: =+E9 -> 6850690
A26: =+CONCATENATE(B26,"-",C26) -> 30000000000-2000000000 | B26: =+$C$9 -> 30000000000 | C26: =+$F$7 -> 2000000000 | D26: =+F9 -> 12570853
A27: =+CONCATENATE(B27,"-",C27) -> 30000000000-3000000000 | B27: =+$C$9 -> 30000000000 | C27: =+$G$7 -> 3000000000 | D27: =+G9 -> 17571777
A28: =+CONCATENATE(B28,"-",C28) -> 30000000000-4000000000 | B28: =+$C$9 -> 30000000000 | C28: =+$H$7 -> 4000000000 | D28: =+H9 -> N/A
A29: =+CONCATENATE(B29,"-",C29) -> 30000000000-5000000000 | B29: =+$C$9 -> 30000000000 | C29: =+$I$7 -> 5000000000 | D29: =+I9 -> N/A
A30: =+CONCATENATE(B30,"-",C30) -> 45000000000-500000000 | B30: =+$C$10 -> 45000000000 | C30: =+$D$7 -> 500000000 | D30: =+D10 -> 4519350
A31: =+CONCATENATE(B31,"-",C31) -> 45000000000-1000000000 | B31: =+$C$10 -> 45000000000 | C31: =+$E$7 -> 1000000000 | D31: =+E10 -> 8563362.5
A32: =+CONCATENATE(B32,"-",C32) -> 45000000000-2000000000 | B32: =+$C$10 -> 45000000000 | C32: =+$F$7 -> 2000000000 | D32: =+F10 -> 14789239
A33: =+CONCATENATE(B33,"-",C33) -> 45000000000-3000000000 | B33: =+$C$10 -> 45000000000 | C33: =+$G$7 -> 3000000000 | D33: =+G10 -> 20082031
A34: =+CONCATENATE(B34,"-",C34) -> 45000000000-4000000000 | B34: =+$C$10 -> 45000000000 | C34: =+$H$7 -> 4000000000 | D34: =+H10 -> N/A
A35: =+CONCATENATE(B35,"-",C35) -> 45000000000-5000000000 | B35: =+$C$10 -> 45000000000 | C35: =+$I$7 -> 5000000000 | D35: =+I10 -> N/A
A36: =+CONCATENATE(B36,"-",C36) -> 60000000000-500000000 | B36: =+$C$11 -> 60000000000 | C36: =+$D$7 -> 500000000 | D36: =+D11 -> 5445000
A37: =+CONCATENATE(B37,"-",C37) -> 60000000000-1000000000 | B37: =+$C$11 -> 60000000000 | C37: =+$E$7 -> 1000000000 | D37: =+E11 -> 9341850
A38: =+CONCATENATE(B38,"-",C38) -> 60000000000-2000000000 | B38: =+$C$11 -> 60000000000 | C38: =+$F$7 -> 2000000000 | D38: =+F11 -> 17747086
A39: =+CONCATENATE(B39,"-",C39) -> 60000000000-3000000000 | B39: =+$C$11 -> 60000000000 | C39: =+$G$7 -> 3000000000 | D39: =+G11 -> 24098437
A40: =+CONCATENATE(B40,"-",C40) -> 60000000000-4000000000 | B40: =+$C$11 -> 60000000000 | C40: =+$H$7 -> 4000000000 | D40: =+H11 -> 29628430
A41: =+CONCATENATE(B41,"-",C41) -> 60000000000-5000000000 | B41: =+$C$11 -> 60000000000 | C41: =+$I$7 -> 5000000000 | D41: =+I11 -> 33669000
A42: =+CONCATENATE(B42,"-",C42) -> 80000000000-500000000 | B42: =+$C$12 -> 80000000000 | C42: =+$D$7 -> 500000000 | D42: =+D12 -> N/A
A43: =+CONCATENATE(B43,"-",C43) -> 80000000000-1000000000 | B43: =+$C$12 -> 80000000000 | C43: =+$E$7 -> 1000000000 | D43: =+E12 -> 11300625
A44: =+CONCATENATE(B44,"-",C44) -> 80000000000-2000000000 | B44: =+$C$12 -> 80000000000 | C44: =+$F$7 -> 2000000000 | D44: =+F12 -> 19718985
A45: =+CONCATENATE(B45,"-",C45) -> 80000000000-3000000000 | B45: =+$C$12 -> 80000000000 | C45: =+$G$7 -> 3000000000 | D45: =+G12 -> 27281250
A46: =+CONCATENATE(B46,"-",C46) -> 80000000000-4000000000 | B46: =+$C$12 -> 80000000000 | C46: =+$H$7 -> 4000000000 | D46: =+H12 -> 32799000
...

Sheet Configuracion CYBER
A1: SI
A2: NO | B2: Limite de indemnizacion | C2: #REF!
A3: N/A
B4: Hasta $1.500.000.000 | C4: 1 | D4: 500000000 | E4: 1000000000
B5: Desde $1.500.000.001 hasta $3.000.000.000 | C5: 2 | D5: 500000000 | E5: 1000000000 | F5: 2000000000
B6: Desde $3.000.000.001 hasta $8.000.000.000 | C6: 3 | D6: 500000000 | E6: 1000000000 | F6: 2000000000 | G6: 3000000000
B7: Desde $8.000.000.001 hasta $15.000.000.000 | C7: 4 | D7: 500000000 | E7: 1000000000 | F7: 2000000000 | G7: 3000000000
B8: Desde $15.000.000.001 hasta $30.000.000.000 | C8: 5 | D8: 500000000 | E8: 1000000000 | F8: 2000000000 | G8: 3000000000 | H8: 5000000000
B9: Desde $30.000.000.001 hasta $60.000.000.000 | C9: 6 | D9: 500000000 | E9: 1000000000 | F9: 2000000000 | G9: 3000000000 | H9: 5000000000
B10: Desde $60.000.000.001 hasta $100.000.000.000 | C10: 7 | D10: 500000000 | E10: 1000000000 | F10: 2000000000 | G10: 3000000000 | H10: 5000000000
B13: Deducible
B14: 500000000 | C14: 25000000 | D14: 1
B15: 1000000000 | C15: 35000000 | D15: 2
B16: 2000000000 | C16: 50000000 | D16: 3
B17: 3000000000 | C17: 50000000 | D17: 4
B18: 5000000000 | C18: 75000000 | D18: 5
B24: PRIMAS Y DEDUCIBLES OFERTA FAST FLOW - V2 10.08.2021
B26: LIMITE DE INDEMNIZACION (*) | D26: 500000000 | E26: 1000000000 | F26: 2000000000 | G26: 3000000000 | H26: 5000000000
B27: FACTURACION TOTAL ANUAL | C27: Hasta $1.500.000.000 | D27: 2800000 | E27: 4200000
C28: Desde $1.500.000.001 hasta $3.000.000.000 | D28: 3025000 | E28: 4537500 | F28: 6810000
C29: Desde $3.000.000.001 hasta $8.000.000.000 | D29: 3630000 | E29: 5445000 | F29: 8167500 | G29: 10210000
C30: Desde $8.000.000.001 hasta $15.000.000.000 | D30: 4537500 | E30: 6806250 | F30: 10210000 | G30: 12762000
C31: Desde $15.000.000.001 hasta $30.000.000.000 | D31: 5445000 | E31: 8167500 | F31: 12251250 | G31: 15315000 | H31: 20420000
C32: Desde $30.000.000.001 hasta $60.000.000.000 | D32: 6262000 | E32: 9395000 | F32: 14090000 | G32: 17612000 | H32: 23482000
C33: Desde $60.000.000.001 hasta $100.000.000.000 | D33: 6890000 | E33: 10332000 | F33: 15498000 | G33: 19374000 | H33: 25830000
B34: DEDUCIBLE (**) | D34: 25000000 | E34: 35000000 | F34: 50000000 | H34: 75000000
B36: Se otorga
B37: No se Otorga
B38: Nuevo
B39: Renovación
B46: Sección | C46: Nombre | D46: Recargo
B47: A | C47: AGRICULTURA, GANADERIA, PRODUCCION FORESTAL, PESCA Y ACUICULTURA | D47: 0
C48: AGRICULTURA, GANADERIA Y SERVICIOS CONEXOS | D48: 0
C49: PRODUCCIÓN FORESTAL | D49: 0
C50: PESCA Y ACUICULTURA | D50: 0
C51: OTROS MISCELANIOS AGRICULTURA, GANADERIA, PRODUCCION FORESTAL, PESCA Y ACUICULTURA | D51: 0
B52: B | C52: INDUSTRIAS DE TRANSFORMACIÓN | D52: 0
C53: FABRICACIÓN DE PRODUCTOS ALIMENTICIOS | D53: 0
C54: FABRICACIÓN DE BEBIDAS | D54: 0
C55: FABRICACIÓN DE PRODUCTOS TEXTILES | D55: 0
...

Sheet CALCULOSD&O
B1: PRIMA BRUTA ANUAL: (ANTES DE DERECHOS E IMPUESTOS)
A2: =ENTRADAS!B4 -> 1000000000 | B2: {=IFERROR(ROUND((IFERROR(INDEX('Configuraciond&o'!$D$35:$P$43,_xlfn.XLOOKUP(ENTRADAS!$B$3,'Configuraciond&o'!$B$6:$B$14,'Configuraciond&o'!$C$6:$C$14,FALSE),_xlfn.XLOOKUP(A2,'Configuraciond&o'!$B$17:$B$29,'Configuraciond&o'!$E$17:$E$29,FALSE)),"N/A"))*(1+C2),-3),"N/A")} -> 2650000
A3: =ENTRADAS!B5 -> 1000000000 | B3: {=IFERROR(ROUND((IFERROR(INDEX('Configuraciond&o'!$D$35:$P$43,_xlfn.XLOOKUP(ENTRADAS!$B$3,'Configuraciond&o'!$B$6:$B$14,'Configuraciond&o'!$C$6:$C$14,FALSE),_xlfn.XLOOKUP(A3,'Configuraciond&o'!$B$17:$B$29,'Configuraciond&o'!$E$17:$E$29,FALSE)),"N/A"))*(1+C3),-3),"N/A")} -> 2650000
A4: =ENTRADAS!B6 -> 1000000000 | B4: {=IFERROR(ROUND((IFERROR(INDEX('Configuraciond&o'!$D$35:$P$43,_xlfn.XLOOKUP(ENTRADAS!$B$3,'Configuraciond&o'!$B$6:$B$14,'Configuraciond&o'!$C$6:$C$14,FALSE),_xlfn.XLOOKUP(A4,'Configuraciond&o'!$B$17:$B$29,'Configuraciond&o'!$E$17:$E$29,FALSE)),"N/A"))*(1+C4),-3),"N/A")} -> 2650000
C8: 1 | D8: =IF(ENTRADAS!$B$9<>"Otros","N/A",IF(ENTRADAS!$B$8="SI",IFERROR(_xlfn.XLOOKUP(A2,'Configuraciond&o'!$B$17:$B$29,'Configuraciond&o'!$C$17:$C$29,FALSE),"N/A"),"N/A")) -> 200000000 | E8: {=IFERROR(+_xlfn.IFS(ENTRADAS!B8="SI","todo y cada Reclamo y en el agregado anual",$F$139="NO","N/A"),"N/A")} -> todo y cada Reclamo y en el agregado anual | H8: =IF(ENTRADAS!$B$9<>"Otros",0,IF(ENTRADAS!$B$8="SI",IFERROR(_xlfn.XLOOKUP(A2,'Configuraciond&o'!$B$17:$B$29,'Configuraciond&o'!$D$17:$D$29,FALSE),"N/A"),"N/A")) -> 15000000
C9: 2 | D9: =IF(ENTRADAS!$B$9<>"Otros","N/A",IF(ENTRADAS!$B$8="SI",IFERROR(_xlfn.XLOOKUP(A3,'Configuraciond&o'!$B$17:$B$29,'Configuraciond&o'!$C$17:$C$29,FALSE),"N/A"),"N/A")) -> 200000000 | E9: {=IFERROR(+_xlfn.IFS(ENTRADAS!B8="SI","todo y cada Reclamo y en el agregado anual",$F$139="NO","N/A"),"N/A")} -> todo y cada Reclamo y en el agregado anual | H9: =IF(ENTRADAS!$B$9<>"Otros",0,IF(ENTRADAS!$B$8="SI",IFERROR(_xlfn.XLOOKUP(A3,'Configuraciond&o'!$B$17:$B$29,'Configuraciond&o'!$D$17:$D$29,FALSE),"N/A"),"N/A")) -> 15000000
C10: 3 | D10: =IF(ENTRADAS!$B$9<>"Otros","N/A",IF(ENTRADAS!$B$8="SI",IFERROR(_xlfn.XLOOKUP(A4,'Configuraciond&o'!$B$17:$B$29,'Configuraciond&o'!$C$17:$C$29,FALSE),"N/A"),"N/A")) -> 200000000 | E10: {=IFERROR(+_xlfn.IFS(ENTRADAS!B8="SI","todo y cada Reclamo y en el agregado anual",$F$139="NO","N/A"),"N/A")} -> todo y cada Reclamo y en el agregado anual | H10: =IF(ENTRADAS!$B$9<>"Otros",0,IF(ENTRADAS!$B$8="SI",IFERROR(_xlfn.XLOOKUP(A4,'Configuraciond&o'!$B$17:$B$29,'Configuraciond&o'!$D$17:$D$29,FALSE),"N/A"),"N/A")) -> 15000000

Sheet CALCULOS INFIDELIDAD DE EMPLEAD
A2: PRIMA ALTERNATIVA 1 | B2: =IFERROR(+_xlfn.XLOOKUP(B8,'Nuevas Primas CYBER'!$E$42:$E$221,'Nuevas Primas CYBER'!$F$42:$F$221,0),"-") -> -
A3: PRIMA ALTERNATIVA 2 | B3: =IFERROR(+_xlfn.XLOOKUP(B9,'Nuevas Primas CYBER'!$E$42:$E$221,'Nuevas Primas CYBER'!$F$42:$F$221,0),"-") -> -
A4: PRIMA ALTERNATIVA 3 | B4: =IFERROR(+_xlfn.XLOOKUP(B10,'Nuevas Primas CYBER'!$E$42:$E$221,'Nuevas Primas CYBER'!$F$42:$F$221,0),"-") -> -
A5: DEDUCIBLE 1 | B5: =IFERROR(+_xlfn.XLOOKUP(ENTRADAS!B16,'Nuevas Primas CYBER'!$V$4:$V$8,'Nuevas Primas CYBER'!$W$4:$W$8,0),"-") -> COP50.000.000
A6: DEDUCIBLE 2 | B6: =IFERROR(+_xlfn.XLOOKUP(ENTRADAS!B17,'Nuevas Primas CYBER'!$V$4:$V$8,'Nuevas Primas CYBER'!$W$4:$W$8,0),"-") -> COP50.000.000
A7: DEDUCIBLE 3 | B7: =IFERROR(+_xlfn.XLOOKUP(ENTRADAS!B18,'Nuevas Primas CYBER'!$V$4:$V$8,'Nuevas Primas CYBER'!$W$4:$W$8,0),"-") -> COP50.000.000
A8: LLAVE 1 | B8: =+CONCATENATE(ENTRADAS!#REF!,"-",ENTRADAS!$B$15,"-",ENTRADAS!B16,"-",ENTRADAS!B19) -> #REF!
A9: LLAVE 2 | B9: =+CONCATENATE(ENTRADAS!#REF!,"-",ENTRADAS!$B$15,"-",ENTRADAS!B17,"-",ENTRADAS!B20) -> #REF!
A10: LLAVE 3 | B10: =+CONCATENATE(ENTRADAS!#REF!,"-",ENTRADAS!$B$15,"-",ENTRADAS!B18,"-",ENTRADAS!B21) -> #REF!
A13: NOTA DE COBERTURA
A14: PRIMA ALTERNATIVA 1 | B14: =B2 -> -
A15: PRIMA ALTERNATIVA 2 | B15: =B3 -> -
A16: PRIMA ALTERNATIVA 3 | B16: =B4 -> -
A17: DEDUCIBLE 1 | B17: =IFERROR(+_xlfn.XLOOKUP(ENTRADAS!#REF!,'Nuevas Primas CYBER'!$V$4:$V$8,'Nuevas Primas CYBER'!$W$4:$W$8,0),"-") -> -
A18: DEDUCIBLE 2 | B18: =IFERROR(+_xlfn.XLOOKUP(ENTRADAS!#REF!,'Nuevas Primas CYBER'!$V$4:$V$8,'Nuevas Primas CYBER'!$W$4:$W$8,0),"-") -> -
A19: DEDUCIBLE 3 | B19: =IFERROR(+_xlfn.XLOOKUP(ENTRADAS!#REF!,'Nuevas Primas CYBER'!$V$4:$V$8,'Nuevas Primas CYBER'!$W$4:$W$8,0),"-") -> -

Sheet Configuraciond&o
B4: Limite de facturación
B6: Hasta COP 7.000.000.000 | C6: 1 | D6: 500000000 | E6: 1000000000
B7: Hasta COP 13.000.000.000 | C7: 2 | D7: 500000000 | E7: 1000000000 | F7: 2000000000
B8: Hasta COP 20.000.000.000 | C8: 3 | D8: 500000000 | E8: 1000000000 | F8: 2000000000 | G8: 3000000000
B9: Hasta COP 45.000.000.000 | C9: 4 | D9: 500000000 | E9: 1000000000 | F9: 2000000000 | G9: 3000000000
B10: Hasta COP 60.000.000.000 | C10: 5
B11: Hasta COP 85.000.000.000 | C11: 6
B12: Hasta COP 120.000.000.000 | C12: 7
B13: Hasta COP 150.000.000.000 | C13: 8
B14: Hasta COP 200.000.000.000 | C14: 9
B16: Límite de responsabilidad | C16: Anexo de cobertura a la Entidad: | D16: DEDUCIBLE PARA ANEXO DE COBERTURA A LA ENTIDAD
B17: 500000000 | C17: =+B17*0.2 -> 100000000 | D17: 10000000 | E17: 1
B18: 1000000000 | C18: =+B18*0.2 -> 200000000 | D18: 15000000 | E18: 2
B19: 1500000000 | C19: =+B19*0.2 -> 300000000 | D19: 20000000 | E19: 3
B20: 2000000000 | C20: =+B20*0.2 -> 400000000 | D20: 25000000 | E20: 4
B21: 3000000000 | C21: =+B21*0.2 -> 600000000 | D21: 30000000 | E21: 5
B22: 4000000000 | C22: =+B22*0.2 -> 800000000 | D22: =+C22*5/100 -> 40000000 | E22: 6
B23: 5000000000 | C23: =+B23*0.2 -> 1000000000 | D23: 45000000 | E23: 7
B24: 6000000000 | C24: =+B24*0.2 -> 1200000000 | D24: 50000000 | E24: 8
B25: 7000000000 | C25: =+B25*0.2 -> 1400000000 | D25: 55000000 | E25: 9
B26: 8000000000 | C26: =+B26*0.2 -> 1600000000 | D26: 65000000 | E26: 10
B27: 9000000000 | C27: =+B27*0.2 -> 1800000000 | D27: 75000000 | E27: 11
B28: 10000000000 | C28: =+B28*0.2 -> 2000000000 | D28: 75000000 | E28: 12
B29: 15000000000 | C29: 2000000000 | D29: 75000000 | E29: 13
B32: PRIMAS Y DEDUCIBLES OFERTA FAST FLOW - V2 10.08.2021
B34: LIMITE DE RESPONSABILIDAD (*) | D34: 500000000 | E34: 1000000000 | F34: 1500000000 | G34: 2000000000 | H34: 3000000000 | I34: 4000000000 | J34: 5000000000 | K34: 6000000000 | L34: 7000000000 | M34: 8000000000 | N34: 9000000000 | O34: 10000000000 | P34: 15000000000
B35: FACTURACION TOTAL ANUAL | C35: Hasta COP 7.000.000.000 | D35: =+'PRIMASd&o'!C8 -> 1542800.9 | E35: =+'PRIMASd&o'!D8 -> 2505891.2 | F35: =+'PRIMASd&o'!E8 -> 3200774 | G35: =+'PRIMASd&o'!F8 -> 4184018.3 | H35: =+'PRIMASd&o'!G8 -> 4988091.2 | I35: =+'PRIMASd&o'!H8 -> 6687115.6 | J35: =+'PRIMASd&o'!I8 -> 8221863.5 | K35: =+'PRIMASd&o'!J8 -> 9461777.7 | ... P35: =+'PRIMASd&o'!O8 -> N/A
C36: Hasta COP 13.000.000.000 | D36: =+'PRIMASd&o'!C9 -> 1647285.9 | E36: =+'PRIMASd&o'!D9 -> 2514272.1 | F36: =+'PRIMASd&o'!E9 -> 3311145.5 | G36: =+'PRIMASd&o'!F9 -> 4328294.8 | H36: =+'PRIMASd&o'!G9 -> 5160094.3 | I36: =+'PRIMASd&o'!H9 -> 6800456.6 | J36: =+'PRIMASd&o'!I9 -> 8361217.1 | K36: =+'PRIMASd&o'!J9 -> 9622146.8 | ... P36: =+'PRIMASd&o'!O9 -> N/A
C37: Hasta COP 20.000.000.000 | D37: =+'PRIMASd&o'!C10 -> 1715647.9 | E37: =+'PRIMASd&o'!D10 -> 2522681 | F37: =+'PRIMASd&o'!E10 -> 3425322.9 | G37: =+'PRIMASd&o'!F10 -> 4477546.3 | H37: =+'PRIMASd&o'!G10 -> 5338028.6 | I37: =+'PRIMASd&o'!H10 -> 6915718.5 | J37: =+'PRIMASd&o'!I10 -> 8502932.6 | K37: =+'PRIMASd&o'!J10 -> 9953944.9 | ... P37: =+'PRIMASd&o'!O10 -> 12138957
C38: Hasta COP 45.000.000.000 | D38: =+'PRIMASd&o'!C11 -> 1890521.1 | E38: =+'PRIMASd&o'!D11 -> 2531118.1 | F38: =+'PRIMASd&o'!E11 -> 3543437.5 | G38: =+'PRIMASd&o'!F11 -> 4631944.4 | H38: =+'PRIMASd&o'!G11 -> 5522098.6 | I38: =+'PRIMASd&o'!H11 -> 7032934.1 | J38: =+'PRIMASd&o'!I11 -> 8647050.1 | K38: =+'PRIMASd&o'!J11 -> 10297184 | ... P38: =+'PRIMASd&o'!O11 -> 12557542
C39: Hasta COP 60.000.000.000 | D39: =+'PRIMASd&o'!C12 -> 1938333.3 | E39: =+'PRIMASd&o'!D12 -> 2539583.3 | F39: =+'PRIMASd&o'!E12 -> 3665625 | G39: =+'PRIMASd&o'!F12 -> 4791666.7 | H39: =+'PRIMASd&o'!G12 -> 5712515.8 | I39: =+'PRIMASd&o'!H12 -> 7152136.4 | J39: =+'PRIMASd&o'!I12 -> 8793610.3 | K39: =+'PRIMASd&o'!J12 -> 10652260 | ... P39: =+'PRIMASd&o'!O12 -> 12990561
C40: Hasta COP 85.000.000.000 | D40: =+'PRIMASd&o'!C13 -> 2000000 | E40: =+'PRIMASd&o'!D13 -> 2650000 | F40: =+'PRIMASd&o'!E13 -> 3825000 | G40: =+'PRIMASd&o'!F13 -> 5000000 | H40: =+'PRIMASd&o'!G13 -> 5960886 | I40: =+'PRIMASd&o'!H13 -> 7463098.8 | J40: =+'PRIMASd&o'!I13 -> 9175941.2 | K40: =+'PRIMASd&o'!J13 -> 11115401 | ... P40: =+'PRIMASd&o'!O13 -> 13555368
C41: Hasta COP 120.000.000.000 | D41: =+'PRIMASd&o'!C14 -> N/A | E41: =+'PRIMASd&o'!D14 -> N/A | F41: =+'PRIMASd&o'!E14 -> N/A | G41: =+'PRIMASd&o'!F14 -> N/A | H41: =+'PRIMASd&o'!G14 -> 6216875 | I41: =+'PRIMASd&o'!H14 -> 7783600 | J41: =+'PRIMASd&o'!I14 -> 9570000 | K41: =+'PRIMASd&o'!J14 -> 11592750 | ... P41: =+'PRIMASd&o'!O14 -> 14137500
C42: Hasta COP 150.000.000.000 | D42: =+'PRIMASd&o'!C15 -> N/A | E42: =+'PRIMASd&o'!D15 -> N/A | F42: =+'PRIMASd&o'!E15 -> N/A | G42: =+'PRIMASd&o'!F15 -> N/A | H42: =+'PRIMASd&o'!G15 -> 7105000 | I42: =+'PRIMASd&o'!H15 -> 9434666.7 | J42: =+'PRIMASd&o'!I15 -> 11600000 | K42: =+'PRIMASd&o'!J15 -> 11890000 | ... P42: =+'PRIMASd&o'!O15 -> 14500000
C43: Hasta COP 200.000.000.000 | D43: =+'PRIMASd&o'!C16 -> N/A | E43: =+'PRIMASd&o'!D16 -> N/A | F43: =+'PRIMASd&o'!E16 -> N/A | G43: =+'PRIMASd&o'!F16 -> N/A | H43: =+'PRIMASd&o'!G16 -> 7350000 | I43: =+'PRIMASd&o'!H16 -> 9760000 | J43: =+'PRIMASd&o'!I16 -> 12000000 | K43: =+'PRIMASd&o'!J16 -> 12300000 | ... P43: =+'PRIMASd&o'!O16 -> 15000000
C45: Anexo | D45: Constr/Cop | E45: Sectores
B46: Nuevo | C46: =IF(ENTRADAS!B9="Otros","SI","NO") -> SI | D46: SI | E46: Otros
B47: Renovación | C47: NO | D47: NO | E47: Copropiedades
E48: Construcción
E49: Educación, escolarización y atención a la infancia
...

Sheet PRIMASd&o
